{"sid": "e1eef8a3d0f2471c95b0f05c2443001e", "uid": null, "qid": "7279e1cbfb30475da722cc2920ffd405", "rid": null, "bars": {"default": {"percent": "100", "remaining": "0"}}, "messages": [{"type": "ERROR", "content": "process - failed executing: [7279e1cbfb30475da722cc2920ffd405]\nTraceback (most recent call last):\n  File \"/home/codespace/.cache/pypoetry/virtualenvs/ai-test-e0q8ujZD-py3.12/lib/python3.12/site-packages/openfabric_pysdk/app/execution/action_dispatcher.py\", line 139, in process\n    output = self.workerContext.execution.execute(data, self.ray, self.state, update)\n             ^^^^^^^^^^^^^^^^^^^^^^^^^^^^^^^^^^^^^^^^^^^^^^^^^^^^^^^^^^^^^^^^^^^^^^^^\n  File \"/home/codespace/.cache/pypoetry/virtualenvs/ai-test-e0q8ujZD-py3.12/lib/python3.12/site-packages/openfabric_pysdk/app/execution/application_interface.py\", line 66, in execute\n    self.execution_function(model)\n  File \"/workspaces/Openfabic/app/main.py\", line 85, in execute\n    image_response = stub.call(\n                     ^^^^^^^^^^\n  File \"/workspaces/Openfabic/app/core/stub.py\", line 85, in call\n    raise Exception(f\"Connection not found for app ID: {app_id}\")\nException: Connection not found for app ID: f0997a01-d6d3-a5fe-53d8-561300318557.node3.openfabric.network\n", "created_at": "2025-06-08T12:00:27.794680"}], "status": "FAILED", "created_at": "2025-06-08T12:00:17.030906", "updated_at": "2025-06-08T12:00:27.794715", "finished": true}